Workbook

Sheet README
A1: Item | B1: Value
A2: Annotator Agreement Manual Review Workbook
A3: Annotator A | B3: 1
A4: Annotator B | B4: (2, 3)
A5: Paired completed documents | B5: 140
A6: Document-feature comparisons | B6: 560
A7: Rows in Review Queue | B7: 63
A9: How to review | B9: Open Review Queue and inspect only the rows where the annotators differ.
A10: TP | B10: Same underlying entity/value annotated by both annotators.
A11: FP | B11: Value annotated only by Annotator 1.
A12: FN | B12: Value annotated only by Annotator (2, 3).
A13: Manual override | B13: Fill ALL THREE manual_TP/manual_FP/manual_FN cells. Partial overrides are flagged INCOMPLETE.
A14: Reviewed text | B14: Edit the two *_reviewed columns when differently worded annotations should be treated as the same value. These reviewed strings are used for the reviewed Cohen's kappa after rerunning the notebook.
A15: Exclude | B15: Set exclude = Yes only when the comparison should not be part of agreement analysis.
... A18: Span differences | B18: Same value at a different occurrence/span is already treated as value-level agreement and does not enter the Review Queue.

Sheet Scores
A1: Feature | B1: Comparisons | C1: Full agreements | D1: Agreement | E1: TP | F1: FP | G1: FN | H1: Precision (A1) | I1: Recall (A1) | J1: F1 | K1: Needs review | L1: Incomplete overrides
A2: Ontvanger | B2: =COUNTIFS('All Comparisons'!$D$2:$D$561,$A2)-COUNTIFS('Review Queue'!$D$2:$D$64,$A2,'Review Queue'!$X$2:$X$64,"Yes") -> 140 | C2: =SUMIFS('All Comparisons'!$R$2:$R$561,'All Comparisons'!$D$2:$D$561,$A2)+SUMIFS('Review Queue'!$AE$2:$AE$64,'Review Queue'!$D$2:$D$64,$A2)-SUMIFS('Review Queue'!$R$2:$R$64,'Review Queue'!$D$2:$D$64,$A2) -> 119 | D2: =IFERROR(C2/B2,0) -> 0.85 | E2: =SUMIFS('All Comparisons'!$O$2:$O$561,'All Comparisons'!$D$2:$D$561,$A2)+SUMIFS('Review Queue'!$AB$2:$AB$64,'Review Queue'!$D$2:$D$64,$A2)-SUMIFS('Review Queue'!$O$2:$O$64,'Review Queue'!$D$2:$D$64,$A2) -> 115 | F2: =SUMIFS('All Comparisons'!$P$2:$P$561,'All Comparisons'!$D$2:$D$561,$A2)+SUMIFS('Review Queue'!$AC$2:$AC$64,'Review Queue'!$D$2:$D$64,$A2)-SUMIFS('Review Queue'!$P$2:$P$64,'Review Queue'!$D$2:$D$64,$A2) -> 6 | G2: =SUMIFS('All Comparisons'!$Q$2:$Q$561,'All Comparisons'!$D$2:$D$561,$A2)+SUMIFS('Review Queue'!$AD$2:$AD$64,'Review Queue'!$D$2:$D$64,$A2)-SUMIFS('Review Queue'!$Q$2:$Q$64,'Review Queue'!$D$2:$D$64,$A2) -> 21 | H2: =IFERROR(E2/(E2+F2),0) -> 0.95041322 | I2: =IFERROR(E2/(E2+G2),0) -> 0.84558824 | J2: =IFERROR(2*H2*I2/(H2+I2),0) -> 0.89494163 | K2: =COUNTIFS('Review Queue'!$D$2:$D$64,$A2,'Review Queue'!$Y$2:$Y$64,"<>Reviewed",'Review Queue'!$X$2:$X$64,"<>Yes") -> 40 | L2: =COUNTIFS('Review Queue'!$D$2:$D$64,$A2,'Review Queue'!$AA$2:$AA$64,"INCOMPLETE") -> 0
A3: Besluitvormend Orgaan | B3: =COUNTIFS('All Comparisons'!$D$2:$D$561,$A3)-COUNTIFS('Review Queue'!$D$2:$D$64,$A3,'Review Queue'!$X$2:$X$64,"Yes") -> 140 | C3: =SUMIFS('All Comparisons'!$R$2:$R$561,'All Comparisons'!$D$2:$D$561,$A3)+SUMIFS('Review Queue'!$AE$2:$AE$64,'Review Queue'!$D$2:$D$64,$A3)-SUMIFS('Review Queue'!$R$2:$R$64,'Review Queue'!$D$2:$D$64,$A3) -> 136 | D3: =IFERROR(C3/B3,0) -> 0.97142857 | E3: =SUMIFS('All Comparisons'!$O$2:$O$561,'All Comparisons'!$D$2:$D$561,$A3)+SUMIFS('Review Queue'!$AB$2:$AB$64,'Review Queue'!$D$2:$D$64,$A3)-SUMIFS('Review Queue'!$O$2:$O$64,'Review Queue'!$D$2:$D$64,$A3) -> 136 | F3: =SUMIFS('All Comparisons'!$P$2:$P$561,'All Comparisons'!$D$2:$D$561,$A3)+SUMIFS('Review Queue'!$AC$2:$AC$64,'Review Queue'!$D$2:$D$64,$A3)-SUMIFS('Review Queue'!$P$2:$P$64,'Review Queue'!$D$2:$D$64,$A3) -> 2 | G3: =SUMIFS('All Comparisons'!$Q$2:$Q$561,'All Comparisons'!$D$2:$D$561,$A3)+SUMIFS('Review Queue'!$AD$2:$AD$64,'Review Queue'!$D$2:$D$64,$A3)-SUMIFS('Review Queue'!$Q$2:$Q$64,'Review Queue'!$D$2:$D$64,$A3) -> 4 | H3: =IFERROR(E3/(E3+F3),0) -> 0.98550725 | I3: =IFERROR(E3/(E3+G3),0) -> 0.97142857 | J3: =IFERROR(2*H3*I3/(H3+I3),0) -> 0.97841727 | K3: =COUNTIFS('Review Queue'!$D$2:$D$64,$A3,'Review Queue'!$Y$2:$Y$64,"<>Reviewed",'Review Queue'!$X$2:$X$64,"<>Yes") -> 8 | L3: =COUNTIFS('Review Queue'!$D$2:$D$64,$A3,'Review Queue'!$AA$2:$AA$64,"INCOMPLETE") -> 0
A4: Rechtshandeling | B4: =COUNTIFS('All Comparisons'!$D$2:$D$561,$A4)-COUNTIFS('Review Queue'!$D$2:$D$64,$A4,'Review Queue'!$X$2:$X$64,"Yes") -> 140 | C4: =SUMIFS('All Comparisons'!$R$2:$R$561,'All Comparisons'!$D$2:$D$561,$A4)+SUMIFS('Review Queue'!$AE$2:$AE$64,'Review Queue'!$D$2:$D$64,$A4)-SUMIFS('Review Queue'!$R$2:$R$64,'Review Queue'!$D$2:$D$64,$A4) -> 138 | D4: =IFERROR(C4/B4,0) -> 0.98571429 | E4: =SUMIFS('All Comparisons'!$O$2:$O$561,'All Comparisons'!$D$2:$D$561,$A4)+SUMIFS('Review Queue'!$AB$2:$AB$64,'Review Queue'!$D$2:$D$64,$A4)-SUMIFS('Review Queue'!$O$2:$O$64,'Review Queue'!$D$2:$D$64,$A4) -> 139 | F4: =SUMIFS('All Comparisons'!$P$2:$P$561,'All Comparisons'!$D$2:$D$561,$A4)+SUMIFS('Review Queue'!$AC$2:$AC$64,'Review Queue'!$D$2:$D$64,$A4)-SUMIFS('Review Queue'!$P$2:$P$64,'Review Queue'!$D$2:$D$64,$A4) -> 2 | G4: =SUMIFS('All Comparisons'!$Q$2:$Q$561,'All Comparisons'!$D$2:$D$561,$A4)+SUMIFS('Review Queue'!$AD$2:$AD$64,'Review Queue'!$D$2:$D$64,$A4)-SUMIFS('Review Queue'!$Q$2:$Q$64,'Review Queue'!$D$2:$D$64,$A4) -> 2 | H4: =IFERROR(E4/(E4+F4),0) -> 0.9858156 | I4: =IFERROR(E4/(E4+G4),0) -> 0.9858156 | J4: =IFERROR(2*H4*I4/(H4+I4),0) -> 0.9858156 | K4: =COUNTIFS('Review Queue'!$D$2:$D$64,$A4,'Review Queue'!$Y$2:$Y$64,"<>Reviewed",'Review Queue'!$X$2:$X$64,"<>Yes") -> 9 | L4: =COUNTIFS('Review Queue'!$D$2:$D$64,$A4,'Review Queue'!$AA$2:$AA$64,"INCOMPLETE") -> 0
A5: Rechtsobject | B5: =COUNTIFS('All Comparisons'!$D$2:$D$561,$A5)-COUNTIFS('Review Queue'!$D$2:$D$64,$A5,'Review Queue'!$X$2:$X$64,"Yes") -> 140 | C5: =SUMIFS('All Comparisons'!$R$2:$R$561,'All Comparisons'!$D$2:$D$561,$A5)+SUMIFS('Review Queue'!$AE$2:$AE$64,'Review Queue'!$D$2:$D$64,$A5)-SUMIFS('Review Queue'!$R$2:$R$64,'Review Queue'!$D$2:$D$64,$A5) -> 139 | D5: =IFERROR(C5/B5,0) -> 0.99285714 | E5: =SUMIFS('All Comparisons'!$O$2:$O$561,'All Comparisons'!$D$2:$D$561,$A5)+SUMIFS('Review Queue'!$AB$2:$AB$64,'Review Queue'!$D$2:$D$64,$A5)-SUMIFS('Review Queue'!$O$2:$O$64,'Review Queue'!$D$2:$D$64,$A5) -> 140 | F5: =SUMIFS('All Comparisons'!$P$2:$P$561,'All Comparisons'!$D$2:$D$561,$A5)+SUMIFS('Review Queue'!$AC$2:$AC$64,'Review Queue'!$D$2:$D$64,$A5)-SUMIFS('Review Queue'!$P$2:$P$64,'Review Queue'!$D$2:$D$64,$A5) -> 1 | G5: =SUMIFS('All Comparisons'!$Q$2:$Q$561,'All Comparisons'!$D$2:$D$561,$A5)+SUMIFS('Review Queue'!$AD$2:$AD$64,'Review Queue'!$D$2:$D$64,$A5)-SUMIFS('Review Queue'!$Q$2:$Q$64,'Review Queue'!$D$2:$D$64,$A5) -> 0 | H5: =IFERROR(E5/(E5+F5),0) -> 0.9929078 | I5: =IFERROR(E5/(E5+G5),0) -> 1 | J5: =IFERROR(2*H5*I5/(H5+I5),0) -> 0.99644128 | K5: =COUNTIFS('Review Queue'!$D$2:$D$64,$A5,'Review Queue'!$Y$2:$Y$64,"<>Reviewed",'Review Queue'!$X$2:$X$64,"<>Yes") -> 6 | L5: =COUNTIFS('Review Queue'!$D$2:$D$64,$A5,'Review Queue'!$AA$2:$AA$64,"INCOMPLETE") -> 0
A6: Overall | B6: =560-COUNTIFS('Review Queue'!$X$2:$X$64,"Yes") -> 560 | C6: =SUM('All Comparisons'!$R$2:$R$561)+SUM('Review Queue'!$AE$2:$AE$64)-SUM('Review Queue'!$R$2:$R$64) -> 532 | D6: =IFERROR(C6/B6,0) -> 0.95 | E6: =SUM('All Comparisons'!$O$2:$O$561)+SUM('Review Queue'!$AB$2:$AB$64)-SUM('Review Queue'!$O$2:$O$64) -> 530 | F6: =SUM('All Comparisons'!$P$2:$P$561)+SUM('Review Queue'!$AC$2:$AC$64)-SUM('Review Queue'!$P$2:$P$64) -> 11 | G6: =SUM('All Comparisons'!$Q$2:$Q$561)+SUM('Review Queue'!$AD$2:$AD$64)-SUM('Review Queue'!$Q$2:$Q$64) -> 27 | H6: =IFERROR(E6/(E6+F6),0) -> 0.97966728 | I6: =IFERROR(E6/(E6+G6),0) -> 0.95152603 | J6: =IFERROR(2*H6*I6/(H6+I6),0) -> 0.96539162 | K6: =COUNTIFS('Review Queue'!$Y$2:$Y$64,"<>Reviewed",'Review Queue'!$X$2:$X$64,"<>Yes") -> 63 | L6: =COUNTIFS('Review Queue'!$AA$2:$AA$64,"INCOMPLETE") -> 0

Sheet Scores by Authority
A1: Authority | B1: Feature | C1: Comparisons | D1: Full agreements | E1: Agreement | F1: TP | G1: FP | H1: FN | I1: Precision (A1) | J1: Recall (A1) | K1: F1 | L1: Needs review | M1: Incomplete overrides
A2: ACM | B2: Ontvanger | C2: =COUNTIFS('All Comparisons'!$C$2:$C$561,$A2,'All Comparisons'!$D$2:$D$561,$B2)-COUNTIFS('Review Queue'!$C$2:$C$64,$A2,'Review Queue'!$D$2:$D$64,$B2,'Review Queue'!$X$2:$X$64,"Yes") -> 20 | D2: =SUMIFS('All Comparisons'!$R$2:$R$561,'All Comparisons'!$C$2:$C$561,$A2,'All Comparisons'!$D$2:$D$561,$B2)+SUMIFS('Review Queue'!$AE$2:$AE$64,'Review Queue'!$C$2:$C$64,$A2,'Review Queue'!$D$2:$D$64,$B2)-SUMIFS('Review Queue'!$R$2:$R$64,'Review Queue'!$C$2:$C$64,$A2,'Review Queue'!$D$2:$D$64,$B2) -> 20 | E2: =IFERROR(D2/C2,0) -> 1 | F2: =SUMIFS('All Comparisons'!$O$2:$O$561,'All Comparisons'!$C$2:$C$561,$A2,'All Comparisons'!$D$2:$D$561,$B2)+SUMIFS('Review Queue'!$AB$2:$AB$64,'Review Queue'!$C$2:$C$64,$A2,'Review Queue'!$D$2:$D$64,$B2)-SUMIFS('Review Queue'!$O$2:$O$64,'Review Queue'!$C$2:$C$64,$A2,'Review Queue'!$D$2:$D$64,$B2) -> 22 | G2: =SUMIFS('All Comparisons'!$P$2:$P$561,'All Comparisons'!$C$2:$C$561,$A2,'All Comparisons'!$D$2:$D$561,$B2)+SUMIFS('Review Queue'!$AC$2:$AC$64,'Review Queue'!$C$2:$C$64,$A2,'Review Queue'!$D$2:$D$64,$B2)-SUMIFS('Review Queue'!$P$2:$P$64,'Review Queue'!$C$2:$C$64,$A2,'Review Queue'!$D$2:$D$64,$B2) -> 0 | H2: =SUMIFS('All Comparisons'!$Q$2:$Q$561,'All Comparisons'!$C$2:$C$561,$A2,'All Comparisons'!$D$2:$D$561,$B2)+SUMIFS('Review Queue'!$AD$2:$AD$64,'Review Queue'!$C$2:$C$64,$A2,'Review Queue'!$D$2:$D$64,$B2)-SUMIFS('Review Queue'!$Q$2:$Q$64,'Review Queue'!$C$2:$C$64,$A2,'Review Queue'!$D$2:$D$64,$B2) -> 0 | I2: =IFERROR(F2/(F2+G2),0) -> 1 | J2: =IFERROR(F2/(F2+H2),0) -> 1 | K2: =IFERROR(2*I2*J2/(I2+J2),0) -> 1 | L2: =COUNTIFS('Review Queue'!$C$2:$C$64,$A2,'Review Queue'!$D$2:$D$64,$B2,'Review Queue'!$Y$2:$Y$64,"<>Reviewed",'Review Queue'!$X$2:$X$64,"<>Yes") -> 2 | M2: =COUNTIFS('Review Queue'!$C$2:$C$64,$A2,'Review Queue'!$D$2:$D$64,$B2,'Review Queue'!$AA$2:$AA$64,"INCOMPLETE") -> 0
A3: ACM | B3: Besluitvormend Orgaan | C3: =COUNTIFS('All Comparisons'!$C$2:$C$561,$A3,'All Comparisons'!$D$2:$D$561,$B3)-COUNTIFS('Review Queue'!$C$2:$C$64,$A3,'Review Queue'!$D$2:$D$64,$B3,'Review Queue'!$X$2:$X$64,"Yes") -> 20 | D3: =SUMIFS('All Comparisons'!$R$2:$R$561,'All Comparisons'!$C$2:$C$561,$A3,'All Comparisons'!$D$2:$D$561,$B3)+SUMIFS('Review Queue'!$AE$2:$AE$64,'Review Queue'!$C$2:$C$64,$A3,'Review Queue'!$D$2:$D$64,$B3)-SUMIFS('Review Queue'!$R$2:$R$64,'Review Queue'!$C$2:$C$64,$A3,'Review Queue'!$D$2:$D$64,$B3) -> 20 | E3: =IFERROR(D3/C3,0) -> 1 | F3: =SUMIFS('All Comparisons'!$O$2:$O$561,'All Comparisons'!$C$2:$C$561,$A3,'All Comparisons'!$D$2:$D$561,$B3)+SUMIFS('Review Queue'!$AB$2:$AB$64,'Review Queue'!$C$2:$C$64,$A3,'Review Queue'!$D$2:$D$64,$B3)-SUMIFS('Review Queue'!$O$2:$O$64,'Review Queue'!$C$2:$C$64,$A3,'Review Queue'!$D$2:$D$64,$B3) -> 20 | G3: =SUMIFS('All Comparisons'!$P$2:$P$561,'All Comparisons'!$C$2:$C$561,$A3,'All Comparisons'!$D$2:$D$561,$B3)+SUMIFS('Review Queue'!$AC$2:$AC$64,'Review Queue'!$C$2:$C$64,$A3,'Review Queue'!$D$2:$D$64,$B3)-SUMIFS('Review Queue'!$P$2:$P$64,'Review Queue'!$C$2:$C$64,$A3,'Review Queue'!$D$2:$D$64,$B3) -> 0 | H3: =SUMIFS('All Comparisons'!$Q$2:$Q$561,'All Comparisons'!$C$2:$C$561,$A3,'All Comparisons'!$D$2:$D$561,$B3)+SUMIFS('Review Queue'!$AD$2:$AD$64,'Review Queue'!$C$2:$C$64,$A3,'Review Queue'!$D$2:$D$64,$B3)-SUMIFS('Review Queue'!$Q$2:$Q$64,'Review Queue'!$C$2:$C$64,$A3,'Review Queue'!$D$2:$D$64,$B3) -> 0 | I3: =IFERROR(F3/(F3+G3),0) -> 1 | J3: =IFERROR(F3/(F3+H3),0) -> 1 | K3: =IFERROR(2*I3*J3/(I3+J3),0) -> 1 | L3: =COUNTIFS('Review Queue'!$C$2:$C$64,$A3,'Review Queue'!$D$2:$D$64,$B3,'Review Queue'!$Y$2:$Y$64,"<>Reviewed",'Review Queue'!$X$2:$X$64,"<>Yes") -> 2 | M3: =COUNTIFS('Review Queue'!$C$2:$C$64,$A3,'Review Queue'!$D$2:$D$64,$B3,'Review Queue'!$AA$2:$AA$64,"INCOMPLETE") -> 0
A4: ACM | B4: Rechtshandeling | C4: =COUNTIFS('All Comparisons'!$C$2:$C$561,$A4,'All Comparisons'!$D$2:$D$561,$B4)-COUNTIFS('Review Queue'!$C$2:$C$64,$A4,'Review Queue'!$D$2:$D$64,$B4,'Review Queue'!$X$2:$X$64,"Yes") -> 20 | D4: =SUMIFS('All Comparisons'!$R$2:$R$561,'All Comparisons'!$C$2:$C$561,$A4,'All Comparisons'!$D$2:$D$561,$B4)+SUMIFS('Review Queue'!$AE$2:$AE$64,'Review Queue'!$C$2:$C$64,$A4,'Review Queue'!$D$2:$D$64,$B4)-SUMIFS('Review Queue'!$R$2:$R$64,'Review Queue'!$C$2:$C$64,$A4,'Review Queue'!$D$2:$D$64,$B4) -> 19 | E4: =IFERROR(D4/C4,0) -> 0.95 | F4: =SUMIFS('All Comparisons'!$O$2:$O$561,'All Comparisons'!$C$2:$C$561,$A4,'All Comparisons'!$D$2:$D$561,$B4)+SUMIFS('Review Queue'!$AB$2:$AB$64,'Review Queue'!$C$2:$C$64,$A4,'Review Queue'!$D$2:$D$64,$B4)-SUMIFS('Review Queue'!$O$2:$O$64,'Review Queue'!$C$2:$C$64,$A4,'Review Queue'!$D$2:$D$64,$B4) -> 19 | G4: =SUMIFS('All Comparisons'!$P$2:$P$561,'All Comparisons'!$C$2:$C$561,$A4,'All Comparisons'!$D$2:$D$561,$B4)+SUMIFS('Review Queue'!$AC$2:$AC$64,'Review Queue'!$C$2:$C$64,$A4,'Review Queue'!$D$2:$D$64,$B4)-SUMIFS('Review Queue'!$P$2:$P$64,'Review Queue'!$C$2:$C$64,$A4,'Review Queue'!$D$2:$D$64,$B4) -> 1 | H4: =SUMIFS('All Comparisons'!$Q$2:$Q$561,'All Comparisons'!$C$2:$C$561,$A4,'All Comparisons'!$D$2:$D$561,$B4)+SUMIFS('Review Queue'!$AD$2:$AD$64,'Review Queue'!$C$2:$C$64,$A4,'Review Queue'!$D$2:$D$64,$B4)-SUMIFS('Review Queue'!$Q$2:$Q$64,'Review Queue'!$C$2:$C$64,$A4,'Review Queue'!$D$2:$D$64,$B4) -> 1 | I4: =IFERROR(F4/(F4+G4),0) -> 0.95 | J4: =IFERROR(F4/(F4+H4),0) -> 0.95 | K4: =IFERROR(2*I4*J4/(I4+J4),0) -> 0.95 | L4: =COUNTIFS('Review Queue'!$C$2:$C$64,$A4,'Review Queue'!$D$2:$D$64,$B4,'Review Queue'!$Y$2:$Y$64,"<>Reviewed",'Review Queue'!$X$2:$X$64,"<>Yes") -> 3 | M4: =COUNTIFS('Review Queue'!$C$2:$C$64,$A4,'Review Queue'!$D$2:$D$64,$B4,'Review Queue'!$AA$2:$AA$64,"INCOMPLETE") -> 0
A5: ACM | B5: Rechtsobject | C5: =COUNTIFS('All Comparisons'!$C$2:$C$561,$A5,'All Comparisons'!$D$2:$D$561,$B5)-COUNTIFS('Review Queue'!$C$2:$C$64,$A5,'Review Queue'!$D$2:$D$64,$B5,'Review Queue'!$X$2:$X$64,"Yes") -> 20 | D5: =SUMIFS('All Comparisons'!$R$2:$R$561,'All Comparisons'!$C$2:$C$561,$A5,'All Comparisons'!$D$2:$D$561,$B5)+SUMIFS('Review Queue'!$AE$2:$AE$64,'Review Queue'!$C$2:$C$64,$A5,'Review Queue'!$D$2:$D$64,$B5)-SUMIFS('Review Queue'!$R$2:$R$64,'Review Queue'!$C$2:$C$64,$A5,'Review Queue'!$D$2:$D$64,$B5) -> 20 | E5: =IFERROR(D5/C5,0) -> 1 | F5: =SUMIFS('All Comparisons'!$O$2:$O$561,'All Comparisons'!$C$2:$C$561,$A5,'All Comparisons'!$D$2:$D$561,$B5)+SUMIFS('Review Queue'!$AB$2:$AB$64,'Review Queue'!$C$2:$C$64,$A5,'Review Queue'!$D$2:$D$64,$B5)-SUMIFS('Review Queue'!$O$2:$O$64,'Review Queue'!$C$2:$C$64,$A5,'Review Queue'!$D$2:$D$64,$B5) -> 21 | G5: =SUMIFS('All Comparisons'!$P$2:$P$561,'All Comparisons'!$C$2:$C$561,$A5,'All Comparisons'!$D$2:$D$561,$B5)+SUMIFS('Review Queue'!$AC$2:$AC$64,'Review Queue'!$C$2:$C$64,$A5,'Review Queue'!$D$2:$D$64,$B5)-SUMIFS('Review Queue'!$P$2:$P$64,'Review Queue'!$C$2:$C$64,$A5,'Review Queue'!$D$2:$D$64,$B5) -> 0 | H5: =SUMIFS('All Comparisons'!$Q$2:$Q$561,'All Comparisons'!$C$2:$C$561,$A5,'All Comparisons'!$D$2:$D$561,$B5)+SUMIFS('Review Queue'!$AD$2:$AD$64,'Review Queue'!$C$2:$C$64,$A5,'Review Queue'!$D$2:$D$64,$B5)-SUMIFS('Review Queue'!$Q$2:$Q$64,'Review Queue'!$C$2:$C$64,$A5,'Review Queue'!$D$2:$D$64,$B5) -> 0 | I5: =IFERROR(F5/(F5+G5),0) -> 1 | J5: =IFERROR(F5/(F5+H5),0) -> 1 | K5: =IFERROR(2*I5*J5/(I5+J5),0) -> 1 | L5: =COUNTIFS('Review Queue'!$C$2:$C$64,$A5,'Review Queue'!$D$2:$D$64,$B5,'Review Queue'!$Y$2:$Y$64,"<>Reviewed",'Review Queue'!$X$2:$X$64,"<>Yes") -> 1 | M5: =COUNTIFS('Review Queue'!$C$2:$C$64,$A5,'Review Queue'!$D$2:$D$64,$B5,'Review Queue'!$AA$2:$AA$64,"INCOMPLETE") -> 0
A6: ACM | B6: Overall | C6: =COUNTIFS('All Comparisons'!$C$2:$C$561,$A6)-COUNTIFS('Review Queue'!$C$2:$C$64,$A6,'Review Queue'!$X$2:$X$64,"Yes") -> 80 | D6: =SUMIFS('All Comparisons'!$R$2:$R$561,'All Comparisons'!$C$2:$C$561,$A6)+SUMIFS('Review Queue'!$AE$2:$AE$64,'Review Queue'!$C$2:$C$64,$A6)-SUMIFS('Review Queue'!$R$2:$R$64,'Review Queue'!$C$2:$C$64,$A6) -> 79 | E6: =IFERROR(D6/C6,0) -> 0.9875 | F6: =SUMIFS('All Comparisons'!$O$2:$O$561,'All Comparisons'!$C$2:$C$561,$A6)+SUMIFS('Review Queue'!$AB$2:$AB$64,'Review Queue'!$C$2:$C$64,$A6)-SUMIFS('Review Queue'!$O$2:$O$64,'Review Queue'!$C$2:$C$64,$A6) -> 82 | G6: =SUMIFS('All Comparisons'!$P$2:$P$561,'All Comparisons'!$C$2:$C$561,$A6)+SUMIFS('Review Queue'!$AC$2:$AC$64,'Review Queue'!$C$2:$C$64,$A6)-SUMIFS('Review Queue'!$P$2:$P$64,'Review Queue'!$C$2:$C$64,$A6) -> 1 | H6: =SUMIFS('All Comparisons'!$Q$2:$Q$561,'All Comparisons'!$C$2:$C$561,$A6)+SUMIFS('Review Queue'!$AD$2:$AD$64,'Review Queue'!$C$2:$C$64,$A6)-SUMIFS('Review Queue'!$Q$2:$Q$64,'Review Queue'!$C$2:$C$64,$A6) -> 1 | I6: =IFERROR(F6/(F6+G6),0) -> 0.98795181 | J6: =IFERROR(F6/(F6+H6),0) -> 0.98795181 | K6: =IFERROR(2*I6*J6/(I6+J6),0) -> 0.98795181 | L6: =COUNTIFS('Review Queue'!$C$2:$C$64,$A6,'Review Queue'!$Y$2:$Y$64,"<>Reviewed",'Review Queue'!$X$2:$X$64,"<>Yes") -> 8 | M6: =COUNTIFS('Review Queue'!$C$2:$C$64,$A6,'Review Queue'!$AA$2:$AA$64,"INCOMPLETE") -> 0
A7: ANVS | B7: Ontvanger | C7: =COUNTIFS('All Comparisons'!$C$2:$C$561,$A7,'All Comparisons'!$D$2:$D$561,$B7)-COUNTIFS('Review Queue'!$C$2:$C$64,$A7,'Review Queue'!$D$2:$D$64,$B7,'Review Queue'!$X$2:$X$64,"Yes") -> 20 | D7: =SUMIFS('All Comparisons'!$R$2:$R$561,'All Comparisons'!$C$2:$C$561,$A7,'All Comparisons'!$D$2:$D$561,$B7)+SUMIFS('Review Queue'!$AE$2:$AE$64,'Review Queue'!$C$2:$C$64,$A7,'Review Queue'!$D$2:$D$64,$B7)-SUMIFS('Review Queue'!$R$2:$R$64,'Review Queue'!$C$2:$C$64,$A7,'Review Queue'!$D$2:$D$64,$B7) -> 20 | E7: =IFERROR(D7/C7,0) -> 1 | F7: =SUMIFS('All Comparisons'!$O$2:$O$561,'All Comparisons'!$C$2:$C$561,$A7,'All Comparisons'!$D$2:$D$561,$B7)+SUMIFS('Review Queue'!$AB$2:$AB$64,'Review Queue'!$C$2:$C$64,$A7,'Review Queue'!$D$2:$D$64,$B7)-SUMIFS('Review Queue'!$O$2:$O$64,'Review Queue'!$C$2:$C$64,$A7,'Review Queue'!$D$2:$D$64,$B7) -> 20 | G7: =SUMIFS('All Comparisons'!$P$2:$P$561,'All Comparisons'!$C$2:$C$561,$A7,'All Comparisons'!$D$2:$D$561,$B7)+SUMIFS('Review Queue'!$AC$2:$AC$64,'Review Queue'!$C$2:$C$64,$A7,'Review Queue'!$D$2:$D$64,$B7)-SUMIFS('Review Queue'!$P$2:$P$64,'Review Queue'!$C$2:$C$64,$A7,'Review Queue'!$D$2:$D$64,$B7) -> 0 | H7: =SUMIFS('All Comparisons'!$Q$2:$Q$561,'All Comparisons'!$C$2:$C$561,$A7,'All Comparisons'!$D$2:$D$561,$B7)+SUMIFS('Review Queue'!$AD$2:$AD$64,'Review Queue'!$C$2:$C$64,$A7,'Review Queue'!$D$2:$D$64,$B7)-SUMIFS('Review Queue'!$Q$2:$Q$64,'Review Queue'!$C$2:$C$64,$A7,'Review Queue'!$D$2:$D$64,$B7) -> 0 | I7: =IFERROR(F7/(F7+G7),0) -> 1 | J7: =IFERROR(F7/(F7+H7),0) -> 1 | K7: =IFERROR(2*I7*J7/(I7+J7),0) -> 1 | L7: =COUNTIFS('Review Queue'!$C$2:$C$64,$A7,'Review Queue'!$D$2:$D$64,$B7,'Review Queue'!$Y$2:$Y$64,"<>Reviewed",'Review Queue'!$X$2:$X$64,"<>Yes") -> 4 | M7: =COUNTIFS('Review Queue'!$C$2:$C$64,$A7,'Review Queue'!$D$2:$D$64,$B7,'Review Queue'!$AA$2:$AA$64,"INCOMPLETE") -> 0
A8: ANVS | B8: Besluitvormend Orgaan | C8: =COUNTIFS('All Comparisons'!$C$2:$C$561,$A8,'All Comparisons'!$D$2:$D$561,$B8)-COUNTIFS('Review Queue'!$C$2:$C$64,$A8,'Review Queue'!$D$2:$D$64,$B8,'Review Queue'!$X$2:$X$64,"Yes") -> 20 | D8: =SUMIFS('All Comparisons'!$R$2:$R$561,'All Comparisons'!$C$2:$C$561,$A8,'All Comparisons'!$D$2:$D$561,$B8)+SUMIFS('Review Queue'!$AE$2:$AE$64,'Review Queue'!$C$2:$C$64,$A8,'Review Queue'!$D$2:$D$64,$B8)-SUMIFS('Review Queue'!$R$2:$R$64,'Review Queue'!$C$2:$C$64,$A8,'Review Queue'!$D$2:$D$64,$B8) -> 20 | E8: =IFERROR(D8/C8,0) -> 1 | F8: =SUMIFS('All Comparisons'!$O$2:$O$561,'All Comparisons'!$C$2:$C$561,$A8,'All Comparisons'!$D$2:$D$561,$B8)+SUMIFS('Review Queue'!$AB$2:$AB$64,'Review Queue'!$C$2:$C$64,$A8,'Review Queue'!$D$2:$D$64,$B8)-SUMIFS('Review Queue'!$O$2:$O$64,'Review Queue'!$C$2:$C$64,$A8,'Review Queue'!$D$2:$D$64,$B8) -> 20 | G8: =SUMIFS('All Comparisons'!$P$2:$P$561,'All Comparisons'!$C$2:$C$561,$A8,'All Comparisons'!$D$2:$D$561,$B8)+SUMIFS('Review Queue'!$AC$2:$AC$64,'Review Queue'!$C$2:$C$64,$A8,'Review Queue'!$D$2:$D$64,$B8)-SUMIFS('Review Queue'!$P$2:$P$64,'Review Queue'!$C$2:$C$64,$A8,'Review Queue'!$D$2:$D$64,$B8) -> 0 | H8: =SUMIFS('All Comparisons'!$Q$2:$Q$561,'All Comparisons'!$C$2:$C$561,$A8,'All Comparisons'!$D$2:$D$561,$B8)+SUMIFS('Review Queue'!$AD$2:$AD$64,'Review Queue'!$C$2:$C$64,$A8,'Review Queue'!$D$2:$D$64,$B8)-SUMIFS('Review Queue'!$Q$2:$Q$64,'Review Queue'!$C$2:$C$64,$A8,'Review Queue'!$D$2:$D$64,$B8) -> 0 | I8: =IFERROR(F8/(F8+G8),0) -> 1 | J8: =IFERROR(F8/(F8+H8),0) -> 1 | K8: =IFERROR(2*I8*J8/(I8+J8),0) -> 1 | L8: =COUNTIFS('Review Queue'!$C$2:$C$64,$A8,'Review Queue'!$D$2:$D$64,$B8,'Review Queue'!$Y$2:$Y$64,"<>Reviewed",'Review Queue'!$X$2:$X$64,"<>Yes") -> 0 | M8: =COUNTIFS('Review Queue'!$C$2:$C$64,$A8,'Review Queue'!$D$2:$D$64,$B8,'Review Queue'!$AA$2:$AA$64,"INCOMPLETE") -> 0
A9: ANVS | B9: Rechtshandeling | C9: =COUNTIFS('All Comparisons'!$C$2:$C$561,$A9,'All Comparisons'!$D$2:$D$561,$B9)-COUNTIFS('Review Queue'!$C$2:$C$64,$A9,'Review Queue'!$D$2:$D$64,$B9,'Review Queue'!$X$2:$X$64,"Yes") -> 20 | D9: =SUMIFS('All Comparisons'!$R$2:$R$561,'All Comparisons'!$C$2:$C$561,$A9,'All Comparisons'!$D$2:$D$561,$B9)+SUMIFS('Review Queue'!$AE$2:$AE$64,'Review Queue'!$C$2:$C$64,$A9,'Review Queue'!$D$2:$D$64,$B9)-SUMIFS('Review Queue'!$R$2:$R$64,'Review Queue'!$C$2:$C$64,$A9,'Review Queue'!$D$2:$D$64,$B9) -> 19 | E9: =IFERROR(D9/C9,0) -> 0.95 | F9: =SUMIFS('All Comparisons'!$O$2:$O$561,'All Comparisons'!$C$2:$C$561,$A9,'All Comparisons'!$D$2:$D$561,$B9)+SUMIFS('Review Queue'!$AB$2:$AB$64,'Review Queue'!$C$2:$C$64,$A9,'Review Queue'!$D$2:$D$64,$B9)-SUMIFS('Review Queue'!$O$2:$O$64,'Review Queue'!$C$2:$C$64,$A9,'Review Queue'!$D$2:$D$64,$B9) -> 20 | G9: =SUMIFS('All Comparisons'!$P$2:$P$561,'All Comparisons'!$C$2:$C$561,$A9,'All Comparisons'!$D$2:$D$561,$B9)+SUMIFS('Review Queue'!$AC$2:$AC$64,'Review Queue'!$C$2:$C$64,$A9,'Review Queue'!$D$2:$D$64,$B9)-SUMIFS('Review Queue'!$P$2:$P$64,'Review Queue'!$C$2:$C$64,$A9,'Review Queue'!$D$2:$D$64,$B9) -> 1 | H9: =SUMIFS('All Comparisons'!$Q$2:$Q$561,'All Comparisons'!$C$2:$C$561,$A9,'All Comparisons'!$D$2:$D$561,$B9)+SUMIFS('Review Queue'!$AD$2:$AD$64,'Review Queue'!$C$2:$C$64,$A9,'Review Queue'!$D$2:$D$64,$B9)-SUMIFS('Review Queue'!$Q$2:$Q$64,'Review Queue'!$C$2:$C$64,$A9,'Review Queue'!$D$2:$D$64,$B9) -> 1 | I9: =IFERROR(F9/(F9+G9),0) -> 0.95238095 | J9: =IFERROR(F9/(F9+H9),0) -> 0.95238095 | K9: =IFERROR(2*I9*J9/(I9+J9),0) -> 0.95238095 | L9: =COUNTIFS('Review Queue'!$C$2:$C$64,$A9,'Review Queue'!$D$2:$D$64,$B9,'Review Queue'!$Y$2:$Y$64,"<>Reviewed",'Review Queue'!$X$2:$X$64,"<>Yes") -> 3 | M9: =COUNTIFS('Review Queue'!$C$2:$C$64,$A9,'Review Queue'!$D$2:$D$64,$B9,'Review Queue'!$AA$2:$AA$64,"INCOMPLETE") -> 0
A10: ANVS | B10: Rechtsobject | C10: =COUNTIFS('All Comparisons'!$C$2:$C$561,$A10,'All Comparisons'!$D$2:$D$561,$B10)-COUNTIFS('Review Queue'!$C$2:$C$64,$A10,'Review Queue'!$D$2:$D$64,$B10,'Review Queue'!$X$2:$X$64,"Yes") -> 20 | D10: =SUMIFS('All Comparisons'!$R$2:$R$561,'All Comparisons'!$C$2:$C$561,$A10,'All Comparisons'!$D$2:$D$561,$B10)+SUMIFS('Review Queue'!$AE$2:$AE$64,'Review Queue'!$C$2:$C$64,$A10,'Review Queue'!$D$2:$D$64,$B10)-SUMIFS('Review Queue'!$R$2:$R$64,'Review Queue'!$C$2:$C$64,$A10,'Review Queue'!$D$2:$D$64,$B10) -> 20 | E10: =IFERROR(D10/C10,0) -> 1 | F10: =SUMIFS('All Comparisons'!$O$2:$O$561,'All Comparisons'!$C$2:$C$561,$A10,'All Comparisons'!$D$2:$D$561,$B10)+SUMIFS('Review Queue'!$AB$2:$AB$64,'Review Queue'!$C$2:$C$64,$A10,'Review Queue'!$D$2:$D$64,$B10)-SUMIFS('Review Queue'!$O$2:$O$64,'Review Queue'!$C$2:$C$64,$A10,'Review Queue'!$D$2:$D$64,$B10) -> 20 | G10: =SUMIFS('All Comparisons'!$P$2:$P$561,'All Comparisons'!$C$2:$C$561,$A10,'All Comparisons'!$D$2:$D$561,$B10)+SUMIFS('Review Queue'!$AC$2:$AC$64,'Review Queue'!$C$2:$C$64,$A10,'Review Queue'!$D$2:$D$64,$B10)-SUMIFS('Review Queue'!$P$2:$P$64,'Review Queue'!$C$2:$C$64,$A10,'Review Queue'!$D$2:$D$64,$B10) -> 0 | H10: =SUMIFS('All Comparisons'!$Q$2:$Q$561,'All Comparisons'!$C$2:$C$561,$A10,'All Comparisons'!$D$2:$D$561,$B10)+SUMIFS('Review Queue'!$AD$2:$AD$64,'Review Queue'!$C$2:$C$64,$A10,'Review Queue'!$D$2:$D$64,$B10)-SUMIFS('Review Queue'!$Q$2:$Q$64,'Review Queue'!$C$2:$C$64,$A10,'Review Queue'!$D$2:$D$64,$B10) -> 0 | I10: =IFERROR(F10/(F10+G10),0) -> 1 | J10: =IFERROR(F10/(F10+H10),0) -> 1 | K10: =IFERROR(2*I10*J10/(I10+J10),0) -> 1 | L10: =COUNTIFS('Review Queue'!$C$2:$C$64,$A10,'Review Queue'!$D$2:$D$64,$B10,'Review Queue'!$Y$2:$Y$64,"<>Reviewed",'Review Queue'!$X$2:$X$64,"<>Yes") -> 0 | M10: =COUNTIFS('Review Queue'!$C$2:$C$64,$A10,'Review Queue'!$D$2:$D$64,$B10,'Review Queue'!$AA$2:$AA$64,"INCOMPLETE") -> 0
A11: ANVS | B11: Overall | C11: =COUNTIFS('All Comparisons'!$C$2:$C$561,$A11)-COUNTIFS('Review Queue'!$C$2:$C$64,$A11,'Review Queue'!$X$2:$X$64,"Yes") -> 80 | D11: =SUMIFS('All Comparisons'!$R$2:$R$561,'All Comparisons'!$C$2:$C$561,$A11)+SUMIFS('Review Queue'!$AE$2:$AE$64,'Review Queue'!$C$2:$C$64,$A11)-SUMIFS('Review Queue'!$R$2:$R$64,'Review Queue'!$C$2:$C$64,$A11) -> 79 | E11: =IFERROR(D11/C11,0) -> 0.9875 | F11: =SUMIFS('All Comparisons'!$O$2:$O$561,'All Comparisons'!$C$2:$C$561,$A11)+SUMIFS('Review Queue'!$AB$2:$AB$64,'Review Queue'!$C$2:$C$64,$A11)-SUMIFS('Review Queue'!$O$2:$O$64,'Review Queue'!$C$2:$C$64,$A11) -> 80 | G11: =SUMIFS('All Comparisons'!$P$2:$P$561,'All Comparisons'!$C$2:$C$561,$A11)+SUMIFS('Review Queue'!$AC$2:$AC$64,'Review Queue'!$C$2:$C$64,$A11)-SUMIFS('Review Queue'!$P$2:$P$64,'Review Queue'!$C$2:$C$64,$A11) -> 1 | H11: =SUMIFS('All Comparisons'!$Q$2:$Q$561,'All Comparisons'!$C$2:$C$561,$A11)+SUMIFS('Review Queue'!$AD$2:$AD$64,'Review Queue'!$C$2:$C$64,$A11)-SUMIFS('Review Queue'!$Q$2:$Q$64,'Review Queue'!$C$2:$C$64,$A11) -> 1 | I11: =IFERROR(F11/(F11+G11),0) -> 0.98765432 | J11: =IFERROR(F11/(F11+H11),0) -> 0.98765432 | K11: =IFERROR(2*I11*J11/(I11+J11),0) -> 0.98765432 | L11: =COUNTIFS('Review Queue'!$C$2:$C$64,$A11,'Review Queue'!$Y$2:$Y$64,"<>Reviewed",'Review Queue'!$X$2:$X$64,"<>Yes") -> 7 | M11: =COUNTIFS('Review Queue'!$C$2:$C$64,$A11,'Review Queue'!$AA$2:$AA$64,"INCOMPLETE") -> 0
A12: AP | B12: Ontvanger | C12: =COUNTIFS('All Comparisons'!$C$2:$C$561,$A12,'All Comparisons'!$D$2:$D$561,$B12)-COUNTIFS('Review Queue'!$C$2:$C$64,$A12,'Review Queue'!$D$2:$D$64,$B12,'Review Queue'!$X$2:$X$64,"Yes") -> 20 | D12: =SUMIFS('All Comparisons'!$R$2:$R$561,'All Comparisons'!$C$2:$C$561,$A12,'All Comparisons'!$D$2:$D$561,$B12)+SUMIFS('Review Queue'!$AE$2:$AE$64,'Review Queue'!$C$2:$C$64,$A12,'Review Queue'!$D$2:$D$64,$B12)-SUMIFS('Review Queue'!$R$2:$R$64,'Review Queue'!$C$2:$C$64,$A12,'Review Queue'!$D$2:$D$64,$B12) -> 20 | E12: =IFERROR(D12/C12,0) -> 1 | F12: =SUMIFS('All Comparisons'!$O$2:$O$561,'All Comparisons'!$C$2:$C$561,$A12,'All Comparisons'!$D$2:$D$561,$B12)+SUMIFS('Review Queue'!$AB$2:$AB$64,'Review Queue'!$C$2:$C$64,$A12,'Review Queue'!$D$2:$D$64,$B12)-SUMIFS('Review Queue'!$O$2:$O$64,'Review Queue'!$C$2:$C$64,$A12,'Review Queue'!$D$2:$D$64,$B12) -> 20 | G12: =SUMIFS('All Comparisons'!$P$2:$P$561,'All Comparisons'!$C$2:$C$561,$A12,'All Comparisons'!$D$2:$D$561,$B12)+SUMIFS('Review Queue'!$AC$2:$AC$64,'Review Queue'!$C$2:$C$64,$A12,'Review Queue'!$D$2:$D$64,$B12)-SUMIFS('Review Queue'!$P$2:$P$64,'Review Queue'!$C$2:$C$64,$A12,'Review Queue'!$D$2:$D$64,$B12) -> 0 | H12: =SUMIFS('All Comparisons'!$Q$2:$Q$561,'All Comparisons'!$C$2:$C$561,$A12,'All Comparisons'!$D$2:$D$561,$B12)+SUMIFS('Review Queue'!$AD$2:$AD$64,'Review Queue'!$C$2:$C$64,$A12,'Review Queue'!$D$2:$D$64,$B12)-SUMIFS('Review Queue'!$Q$2:$Q$64,'Review Queue'!$C$2:$C$64,$A12,'Review Queue'!$D$2:$D$64,$B12) -> 0 | I12: =IFERROR(F12/(F12+G12),0) -> 1 | J12: =IFERROR(F12/(F12+H12),0) -> 1 | K12: =IFERROR(2*I12*J12/(I12+J12),0) -> 1 | L12: =COUNTIFS('Review Queue'!$C$2:$C$64,$A12,'Review Queue'!$D$2:$D$64,$B12,'Review Queue'!$Y$2:$Y$64,"<>Reviewed",'Review Queue'!$X$2:$X$64,"<>Yes") -> 9 | M12: =COUNTIFS('Review Queue'!$C$2:$C$64,$A12,'Review Queue'!$D$2:$D$64,$B12,'Review Queue'!$AA$2:$AA$64,"INCOMPLETE") -> 0
A13: AP | B13: Besluitvormend Orgaan | C13: =COUNTIFS('All Comparisons'!$C$2:$C$561,$A13,'All Comparisons'!$D$2:$D$561,$B13)-COUNTIFS('Review Queue'!$C$2:$C$64,$A13,'Review Queue'!$D$2:$D$64,$B13,'Review Queue'!$X$2:$X$64,"Yes") -> 20 | D13: =SUMIFS('All Comparisons'!$R$2:$R$561,'All Comparisons'!$C$2:$C$561,$A13,'All Comparisons'!$D$2:$D$561,$B13)+SUMIFS('Review Queue'!$AE$2:$AE$64,'Review Queue'!$C$2:$C$64,$A13,'Review Queue'!$D$2:$D$64,$B13)-SUMIFS('Review Queue'!$R$2:$R$64,'Review Queue'!$C$2:$C$64,$A13,'Review Queue'!$D$2:$D$64,$B13) -> 20 | E13: =IFERROR(D13/C13,0) -> 1 | F13: =SUMIFS('All Comparisons'!$O$2:$O$561,'All Comparisons'!$C$2:$C$561,$A13,'All Comparisons'!$D$2:$D$561,$B13)+SUMIFS('Review Queue'!$AB$2:$AB$64,'Review Queue'!$C$2:$C$64,$A13,'Review Queue'!$D$2:$D$64,$B13)-SUMIFS('Review Queue'!$O$2:$O$64,'Review Queue'!$C$2:$C$64,$A13,'Review Queue'!$D$2:$D$64,$B13) -> 20 | G13: =SUMIFS('All Comparisons'!$P$2:$P$561,'All Comparisons'!$C$2:$C$561,$A13,'All Comparisons'!$D$2:$D$561,$B13)+SUMIFS('Review Queue'!$AC$2:$AC$64,'Review Queue'!$C$2:$C$64,$A13,'Review Queue'!$D$2:$D$64,$B13)-SUMIFS('Review Queue'!$P$2:$P$64,'Review Queue'!$C$2:$C$64,$A13,'Review Queue'!$D$2:$D$64,$B13) -> 0 | H13: =SUMIFS('All Comparisons'!$Q$2:$Q$561,'All Comparisons'!$C$2:$C$561,$A13,'All Comparisons'!$D$2:$D$561,$B13)+SUMIFS('Review Queue'!$AD$2:$AD$64,'Review Queue'!$C$2:$C$64,$A13,'Review Queue'!$D$2:$D$64,$B13)-SUMIFS('Review Queue'!$Q$2:$Q$64,'Review Queue'!$C$2:$C$64,$A13,'Review Queue'!$D$2:$D$64,$B13) -> 0 | I13: =IFERROR(F13/(F13+G13),0) -> 1 | J13: =IFERROR(F13/(F13+H13),0) -> 1 | K13: =IFERROR(2*I13*J13/(I13+J13),0) -> 1 | L13: =COUNTIFS('Review Queue'!$C$2:$C$64,$A13,'Review Queue'!$D$2:$D$64,$B13,'Review Queue'!$Y$2:$Y$64,"<>Reviewed",'Review Queue'!$X$2:$X$64,"<>Yes") -> 1 | M13: =COUNTIFS('Review Queue'!$C$2:$C$64,$A13,'Review Queue'!$D$2:$D$64,$B13,'Review Queue'!$AA$2:$AA$64,"INCOMPLETE") -> 0
A14: AP | B14: Rechtshandeling | C14: =COUNTIFS('All Comparisons'!$C$2:$C$561,$A14,'All Comparisons'!$D$2:$D$561,$B14)-COUNTIFS('Review Queue'!$C$2:$C$64,$A14,'Review Queue'!$D$2:$D$64,$B14,'Review Queue'!$X$2:$X$64,"Yes") -> 20 | D14: =SUMIFS('All Comparisons'!$R$2:$R$561,'All Comparisons'!$C$2:$C$561,$A14,'All Comparisons'!$D$2:$D$561,$B14)+SUMIFS('Review Queue'!$AE$2:$AE$64,'Review Queue'!$C$2:$C$64,$A14,'Review Queue'!$D$2:$D$64,$B14)-SUMIFS('Review Queue'!$R$2:$R$64,'Review Queue'!$C$2:$C$64,$A14,'Review Queue'!$D$2:$D$64,$B14) -> 20 | E14: =IFERROR(D14/C14,0) -> 1 | F14: =SUMIFS('All Comparisons'!$O$2:$O$561,'All Comparisons'!$C$2:$C$561,$A14,'All Comparisons'!$D$2:$D$561,$B14)+SUMIFS('Review Queue'!$AB$2:$AB$64,'Review Queue'!$C$2:$C$64,$A14,'Review Queue'!$D$2:$D$64,$B14)-SUMIFS('Review Queue'!$O$2:$O$64,'Review Queue'!$C$2:$C$64,$A14,'Review Queue'!$D$2:$D$64,$B14) -> 20 | G14: =SUMIFS('All Comparisons'!$P$2:$P$561,'All Comparisons'!$C$2:$C$561,$A14,'All Comparisons'!$D$2:$D$561,$B14)+SUMIFS('Review Queue'!$AC$2:$AC$64,'Review Queue'!$C$2:$C$64,$A14,'Review Queue'!$D$2:$D$64,$B14)-SUMIFS('Review Queue'!$P$2:$P$64,'Review Queue'!$C$2:$C$64,$A14,'Review Queue'!$D$2:$D$64,$B14) -> 0 | H14: =SUMIFS('All Comparisons'!$Q$2:$Q$561,'All Comparisons'!$C$2:$C$561,$A14,'All Comparisons'!$D$2:$D$561,$B14)+SUMIFS('Review Queue'!$AD$2:$AD$64,'Review Queue'!$C$2:$C$64,$A14,'Review Queue'!$D$2:$D$64,$B14)-SUMIFS('Review Queue'!$Q$2:$Q$64,'Review Queue'!$C$2:$C$64,$A14,'Review Queue'!$D$2:$D$64,$B14) -> 0 | I14: =IFERROR(F14/(F14+G14),0) -> 1 | J14: =IFERROR(F14/(F14+H14),0) -> 1 | K14: =IFERROR(2*I14*J14/(I14+J14),0) -> 1 | L14: =COUNTIFS('Review Queue'!$C$2:$C$64,$A14,'Review Queue'!$D$2:$D$64,$B14,'Review Queue'!$Y$2:$Y$64,"<>Reviewed",'Review Queue'!$X$2:$X$64,"<>Yes") -> 1 | M14: =COUNTIFS('Review Queue'!$C$2:$C$64,$A14,'Review Queue'!$D$2:$D$64,$B14,'Review Queue'!$AA$2:$AA$64,"INCOMPLETE") -> 0
A15: AP | B15: Rechtsobject | C15: =COUNTIFS('All Comparisons'!$C$2:$C$561,$A15,'All Comparisons'!$D$2:$D$561,$B15)-COUNTIFS('Review Queue'!$C$2:$C$64,$A15,'Review Queue'!$D$2:$D$64,$B15,'Review Queue'!$X$2:$X$64,"Yes") -> 20 | D15: =SUMIFS('All Comparisons'!$R$2:$R$561,'All Comparisons'!$C$2:$C$561,$A15,'All Comparisons'!$D$2:$D$561,$B15)+SUMIFS('Review Queue'!$AE$2:$AE$64,'Review Queue'!$C$2:$C$64,$A15,'Review Queue'!$D$2:$D$64,$B15)-SUMIFS('Review Queue'!$R$2:$R$64,'Review Queue'!$C$2:$C$64,$A15,'Review Queue'!$D$2:$D$64,$B15) -> 19 | E15: =IFERROR(D15/C15,0) -> 0.95 | F15: =SUMIFS('All Comparisons'!$O$2:$O$561,'All Comparisons'!$C$2:$C$561,$A15,'All Comparisons'!$D$2:$D$561,$B15)+SUMIFS('Review Queue'!$AB$2:$AB$64,'Review Queue'!$C$2:$C$64,$A15,'Review Queue'!$D$2:$D$64,$B15)-SUMIFS('Review Queue'!$O$2:$O$64,'Review Queue'!$C$2:$C$64,$A15,'Review Queue'!$D$2:$D$64,$B15) -> 19 | G15: =SUMIFS('All Comparisons'!$P$2:$P$561,'All Comparisons'!$C$2:$C$561,$A15,'All Comparisons'!$D$2:$D$561,$B15)+SUMIFS('Review Queue'!$AC$2:$AC$64,'Review Queue'!$C$2:$C$64,$A15,'Review Queue'!$D$2:$D$64,$B15)-SUMIFS('Review Queue'!$P$2:$P$64,'Review Queue'!$C$2:$C$64,$A15,'Review Queue'!$D$2:$D$64,$B15) -> 1 | H15: =SUMIFS('All Comparisons'!$Q$2:$Q$561,'All Comparisons'!$C$2:$C$561,$A15,'All Comparisons'!$D$2:$D$561,$B15)+SUMIFS('Review Queue'!$AD$2:$AD$64,'Review Queue'!$C$2:$C$64,$A15,'Review Queue'!$D$2:$D$64,$B15)-SUMIFS('Review Queue'!$Q$2:$Q$64,'Review Queue'!$C$2:$C$64,$A15,'Review Queue'!$D$2:$D$64,$B15) -> 0 | I15: =IFERROR(F15/(F15+G15),0) -> 0.95 | J15: =IFERROR(F15/(F15+H15),0) -> 1 | K15: =IFERROR(2*I15*J15/(I15+J15),0) -> 0.97435897 | L15: =COUNTIFS('Review Queue'!$C$2:$C$64,$A15,'Review Queue'!$D$2:$D$64,$B15,'Review Queue'!$Y$2:$Y$64,"<>Reviewed",'Review Queue'!$X$2:$X$64,"<>Yes") -> 1 | M15: =COUNTIFS('Review Queue'!$C$2:$C$64,$A15,'Review Queue'!$D$2:$D$64,$B15,'Review Queue'!$AA$2:$AA$64,"INCOMPLETE") -> 0
A16: AP | B16: Overall | C16: =COUNTIFS('All Comparisons'!$C$2:$C$561,$A16)-COUNTIFS('Review Queue'!$C$2:$C$64,$A16,'Review Queue'!$X$2:$X$64,"Yes") -> 80 | D16: =SUMIFS('All Comparisons'!$R$2:$R$561,'All Comparisons'!$C$2:$C$561,$A16)+SUMIFS('Review Queue'!$AE$2:$AE$64,'Review Queue'!$C$2:$C$64,$A16)-SUMIFS('Review Queue'!$R$2:$R$64,'Review Queue'!$C$2:$C$64,$A16) -> 79 | E16: =IFERROR(D16/C16,0) -> 0.9875 | F16: =SUMIFS('All Comparisons'!$O$2:$O$561,'All Comparisons'!$C$2:$C$561,$A16)+SUMIFS('Review Queue'!$AB$2:$AB$64,'Review Queue'!$C$2:$C$64,$A16)-SUMIFS('Review Queue'!$O$2:$O$64,'Review Queue'!$C$2:$C$64,$A16) -> 79 | G16: =SUMIFS('All Comparisons'!$P$2:$P$561,'All Comparisons'!$C$2:$C$561,$A16)+SUMIFS('Review Queue'!$AC$2:$AC$64,'Review Queue'!$C$2:$C$64,$A16)-SUMIFS('Review Queue'!$P$2:$P$64,'Review Queue'!$C$2:$C$64,$A16) -> 1 | H16: =SUMIFS('All Comparisons'!$Q$2:$Q$561,'All Comparisons'!$C$2:$C$561,$A16)+SUMIFS('Review Queue'!$AD$2:$AD$64,'Review Queue'!$C$2:$C$64,$A16)-SUMIFS('Review Queue'!$Q$2:$Q$64,'Review Queue'!$C$2:$C$64,$A16) -> 0 | I16: =IFERROR(F16/(F16+G16),0) -> 0.9875 | J16: =IFERROR(F16/(F16+H16),0) -> 1 | K16: =IFERROR(2*I16*J16/(I16+J16),0) -> 0.99371069 | L16: =COUNTIFS('Review Queue'!$C$2:$C$64,$A16,'Review Queue'!$Y$2:$Y$64,"<>Reviewed",'Review Queue'!$X$2:$X$64,"<>Yes") -> 12 | M16: =COUNTIFS('Review Queue'!$C$2:$C$64,$A16,'Review Queue'!$AA$2:$AA$64,"INCOMPLETE") -> 0
A17: DRE | B17: Ontvanger | C17: =COUNTIFS('All Comparisons'!$C$2:$C$561,$A17,'All Comparisons'!$D$2:$D$561,$B17)-COUNTIFS('Review Queue'!$C$2:$C$64,$A17,'Review Queue'!$D$2:$D$64,$B17,'Review Queue'!$X$2:$X$64,"Yes") -> 20 | D17: =SUMIFS('All Comparisons'!$R$2:$R$561,'All Comparisons'!$C$2:$C$561,$A17,'All Comparisons'!$D$2:$D$561,$B17)+SUMIFS('Review Queue'!$AE$2:$AE$64,'Review Queue'!$C$2:$C$64,$A17,'Review Queue'!$D$2:$D$64,$B17)-SUMIFS('Review Queue'!$R$2:$R$64,'Review Queue'!$C$2:$C$64,$A17,'Review Queue'!$D$2:$D$64,$B17) -> 18 | E17: =IFERROR(D17/C17,0) -> 0.9 | F17: =SUMIFS('All Comparisons'!$O$2:$O$561,'All Comparisons'!$C$2:$C$561,$A17,'All Comparisons'!$D$2:$D$561,$B17)+SUMIFS('Review Queue'!$AB$2:$AB$64,'Review Queue'!$C$2:$C$64,$A17,'Review Queue'!$D$2:$D$64,$B17)-SUMIFS('Review Queue'!$O$2:$O$64,'Review Queue'!$C$2:$C$64,$A17,'Review Queue'!$D$2:$D$64,$B17) -> 18 | G17: =SUMIFS('All Comparisons'!$P$2:$P$561,'All Comparisons'!$C$2:$C$561,$A17,'All Comparisons'!$D$2:$D$561,$B17)+SUMIFS('Review Queue'!$AC$2:$AC$64,'Review Queue'!$C$2:$C$64,$A17,'Review Queue'!$D$2:$D$64,$B17)-SUMIFS('Review Queue'!$P$2:$P$64,'Review Queue'!$C$2:$C$64,$A17,'Review Queue'!$D$2:$D$64,$B17) -> 1 | H17: =SUMIFS('All Comparisons'!$Q$2:$Q$561,'All Comparisons'!$C$2:$C$561,$A17,'All Comparisons'!$D$2:$D$561,$B17)+SUMIFS('Review Queue'!$AD$2:$AD$64,'Review Queue'!$C$2:$C$64,$A17,'Review Queue'!$D$2:$D$64,$B17)-SUMIFS('Review Queue'!$Q$2:$Q$64,'Review Queue'!$C$2:$C$64,$A17,'Review Queue'!$D$2:$D$64,$B17) -> 2 | I17: =IFERROR(F17/(F17+G17),0) -> 0.94736842 | J17: =IFERROR(F17/(F17+H17),0) -> 0.9 | K17: =IFERROR(2*I17*J17/(I17+J17),0) -> 0.92307692 | L17: =COUNTIFS('Review Queue'!$C$2:$C$64,$A17,'Review Queue'!$D$2:$D$64,$B17,'Review Queue'!$Y$2:$Y$64,"<>Reviewed",'Review Queue'!$X$2:$X$64,"<>Yes") -> 3 | M17: =COUNTIFS('Review Queue'!$C$2:$C$64,$A17,'Review Queue'!$D$2:$D$64,$B17,'Review Queue'!$AA$2:$AA$64,"INCOMPLETE") -> 0
A18: DRE | B18: Besluitvormend Orgaan | C18: =COUNTIFS('All Comparisons'!$C$2:$C$561,$A18,'All Comparisons'!$D$2:$D$561,$B18)-COUNTIFS('Review Queue'!$C$2:$C$64,$A18,'Review Queue'!$D$2:$D$64,$B18,'Review Queue'!$X$2:$X$64,"Yes") -> 20 | D18: =SUMIFS('All Comparisons'!$R$2:$R$561,'All Comparisons'!$C$2:$C$561,$A18,'All Comparisons'!$D$2:$D$561,$B18)+SUMIFS('Review Queue'!$AE$2:$AE$64,'Review Queue'!$C$2:$C$64,$A18,'Review Queue'!$D$2:$D$64,$B18)-SUMIFS('Review Queue'!$R$2:$R$64,'Review Queue'!$C$2:$C$64,$A18,'Review Queue'!$D$2:$D$64,$B18) -> 19 | E18: =IFERROR(D18/C18,0) -> 0.95 | F18: =SUMIFS('All Comparisons'!$O$2:$O$561,'All Comparisons'!$C$2:$C$561,$A18,'All Comparisons'!$D$2:$D$561,$B18)+SUMIFS('Review Queue'!$AB$2:$AB$64,'Review Queue'!$C$2:$C$64,$A18,'Review Queue'!$D$2:$D$64,$B18)-SUMIFS('Review Queue'!$O$2:$O$64,'Review Queue'!$C$2:$C$64,$A18,'Review Queue'!$D$2:$D$64,$B18) -> 19 | G18: =SUMIFS('All Comparisons'!$P$2:$P$561,'All Comparisons'!$C$2:$C$561,$A18,'All Comparisons'!$D$2:$D$561,$B18)+SUMIFS('Review Queue'!$AC$2:$AC$64,'Review Queue'!$C$2:$C$64,$A18,'Review Queue'!$D$2:$D$64,$B18)-SUMIFS('Review Queue'!$P$2:$P$64,'Review Queue'!$C$2:$C$64,$A18,'Review Queue'!$D$2:$D$64,$B18) -> 1 | H18: =SUMIFS('All Comparisons'!$Q$2:$Q$561,'All Comparisons'!$C$2:$C$561,$A18,'All Comparisons'!$D$2:$D$561,$B18)+SUMIFS('Review Queue'!$AD$2:$AD$64,'Review Queue'!$C$2:$C$64,$A18,'Review Queue'!$D$2:$D$64,$B18)-SUMIFS('Review Queue'!$Q$2:$Q$64,'Review Queue'!$C$2:$C$64,$A18,'Review Queue'!$D$2:$D$64,$B18) -> 1 | I18: =IFERROR(F18/(F18+G18),0) -> 0.95 | J18: =IFERROR(F18/(F18+H18),0) -> 0.95 | K18: =IFERROR(2*I18*J18/(I18+J18),0) -> 0.95 | L18: =COUNTIFS('Review Queue'!$C$2:$C$64,$A18,'Review Queue'!$D$2:$D$64,$B18,'Review Queue'!$Y$2:$Y$64,"<>Reviewed",'Review Queue'!$X$2:$X$64,"<>Yes") -> 1 | M18: =COUNTIFS('Review Queue'!$C$2:$C$64,$A18,'Review Queue'!$D$2:$D$64,$B18,'Review Queue'!$AA$2:$AA$64,"INCOMPLETE") -> 0
A19: DRE | B19: Rechtshandeling | C19: =COUNTIFS('All Comparisons'!$C$2:$C$561,$A19,'All Comparisons'!$D$2:$D$561,$B19)-COUNTIFS('Review Queue'!$C$2:$C$64,$A19,'Review Queue'!$D$2:$D$64,$B19,'Review Queue'!$X$2:$X$64,"Yes") -> 20 | D19: =SUMIFS('All Comparisons'!$R$2:$R$561,'All Comparisons'!$C$2:$C$561,$A19,'All Comparisons'!$D$2:$D$561,$B19)+SUMIFS('Review Queue'!$AE$2:$AE$64,'Review Queue'!$C$2:$C$64,$A19,'Review Queue'!$D$2:$D$64,$B19)-SUMIFS('Review Queue'!$R$2:$R$64,'Review Queue'!$C$2:$C$64,$A19,'Review Queue'!$D$2:$D$64,$B19) -> 20 | E19: =IFERROR(D19/C19,0) -> 1 | F19: =SUMIFS('All Comparisons'!$O$2:$O$561,'All Comparisons'!$C$2:$C$561,$A19,'All Comparisons'!$D$2:$D$561,$B19)+SUMIFS('Review Queue'!$AB$2:$AB$64,'Review Queue'!$C$2:$C$64,$A19,'Review Queue'!$D$2:$D$64,$B19)-SUMIFS('Review Queue'!$O$2:$O$64,'Review Queue'!$C$2:$C$64,$A19,'Review Queue'!$D$2:$D$64,$B19) -> 20 | G19: =SUMIFS('All Comparisons'!$P$2:$P$561,'All Comparisons'!$C$2:$C$561,$A19,'All Comparisons'!$D$2:$D$561,$B19)+SUMIFS('Review Queue'!$AC$2:$AC$64,'Review Queue'!$C$2:$C$64,$A19,'Review Queue'!$D$2:$D$64,$B19)-SUMIFS('Review Queue'!$P$2:$P$64,'Review Queue'!$C$2:$C$64,$A19,'Review Queue'!$D$2:$D$64,$B19) -> 0 | H19: =SUMIFS('All Comparisons'!$Q$2:$Q$561,'All Comparisons'!$C$2:$C$561,$A19,'All Comparisons'!$D$2:$D$561,$B19)+SUMIFS('Review Queue'!$AD$2:$AD$64,'Review Queue'!$C$2:$C$64,$A19,'Review Queue'!$D$2:$D$64,$B19)-SUMIFS('Review Queue'!$Q$2:$Q$64,'Review Queue'!$C$2:$C$64,$A19,'Review Queue'!$D$2:$D$64,$B19) -> 0 | I19: =IFERROR(F19/(F19+G19),0) -> 1 | J19: =IFERROR(F19/(F19+H19),0) -> 1 | K19: =IFERROR(2*I19*J19/(I19+J19),0) -> 1 | L19: =COUNTIFS('Review Queue'!$C$2:$C$64,$A19,'Review Queue'!$D$2:$D$64,$B19,'Review Queue'!$Y$2:$Y$64,"<>Reviewed",'Review Queue'!$X$2:$X$64,"<>Yes") -> 1 | M19: =COUNTIFS('Review Queue'!$C$2:$C$64,$A19,'Review Queue'!$D$2:$D$64,$B19,'Review Queue'!$AA$2:$AA$64,"INCOMPLETE") -> 0
A20: DRE | B20: Rechtsobject | C20: =COUNTIFS('All Comparisons'!$C$2:$C$561,$A20,'All Comparisons'!$D$2:$D$561,$B20)-COUNTIFS('Review Queue'!$C$2:$C$64,$A20,'Review Queue'!$D$2:$D$64,$B20,'Review Queue'!$X$2:$X$64,"Yes") -> 20 | D20: =SUMIFS('All Comparisons'!$R$2:$R$561,'All Comparisons'!$C$2:$C$561,$A20,'All Comparisons'!$D$2:$D$561,$B20)+SUMIFS('Review Queue'!$AE$2:$AE$64,'Review Queue'!$C$2:$C$64,$A20,'Review Queue'!$D$2:$D$64,$B20)-SUMIFS('Review Queue'!$R$2:$R$64,'Review Queue'!$C$2:$C$64,$A20,'Review Queue'!$D$2:$D$64,$B20) -> 20 | E20: =IFERROR(D20/C20,0) -> 1 | F20: =SUMIFS('All Comparisons'!$O$2:$O$561,'All Comparisons'!$C$2:$C$561,$A20,'All Comparisons'!$D$2:$D$561,$B20)+SUMIFS('Review Queue'!$AB$2:$AB$64,'Review Queue'!$C$2:$C$64,$A20,'Review Queue'!$D$2:$D$64,$B20)-SUMIFS('Review Queue'!$O$2:$O$64,'Review Queue'!$C$2:$C$64,$A20,'Review Queue'!$D$2:$D$64,$B20) -> 20 | G20: =SUMIFS('All Comparisons'!$P$2:$P$561,'All Comparisons'!$C$2:$C$561,$A20,'All Comparisons'!$D$2:$D$561,$B20)+SUMIFS('Review Queue'!$AC$2:$AC$64,'Review Queue'!$C$2:$C$64,$A20,'Review Queue'!$D$2:$D$64,$B20)-SUMIFS('Review Queue'!$P$2:$P$64,'Review Queue'!$C$2:$C$64,$A20,'Review Queue'!$D$2:$D$64,$B20) -> 0 | H20: =SUMIFS('All Comparisons'!$Q$2:$Q$561,'All Comparisons'!$C$2:$C$561,$A20,'All Comparisons'!$D$2:$D$561,$B20)+SUMIFS('Review Queue'!$AD$2:$AD$64,'Review Queue'!$C$2:$C$64,$A20,'Review Queue'!$D$2:$D$64,$B20)-SUMIFS('Review Queue'!$Q$2:$Q$64,'Review Queue'!$C$2:$C$64,$A20,'Review Queue'!$D$2:$D$64,$B20) -> 0 | I20: =IFERROR(F20/(F20+G20),0) -> 1 | J20: =IFERROR(F20/(F20+H20),0) -> 1 | K20: =IFERROR(2*I20*J20/(I20+J20),0) -> 1 | L20: =COUNTIFS('Review Queue'!$C$2:$C$64,$A20,'Review Queue'!$D$2:$D$64,$B20,'Review Queue'!$Y$2:$Y$64,"<>Reviewed",'Review Queue'!$X$2:$X$64,"<>Yes") -> 0 | M20: =COUNTIFS('Review Queue'!$C$2:$C$64,$A20,'Review Queue'!$D$2:$D$64,$B20,'Review Queue'!$AA$2:$AA$64,"INCOMPLETE") -> 0
A21: DRE | B21: Overall | C21: =COUNTIFS('All Comparisons'!$C$2:$C$561,$A21)-COUNTIFS('Review Queue'!$C$2:$C$64,$A21,'Review Queue'!$X$2:$X$64,"Yes") -> 80 | D21: =SUMIFS('All Comparisons'!$R$2:$R$561,'All Comparisons'!$C$2:$C$561,$A21)+SUMIFS('Review Queue'!$AE$2:$AE$64,'Review Queue'!$C$2:$C$64,$A21)-SUMIFS('Review Queue'!$R$2:$R$64,'Review Queue'!$C$2:$C$64,$A21) -> 77 | E21: =IFERROR(D21/C21,0) -> 0.9625 | F21: =SUMIFS('All Comparisons'!$O$2:$O$561,'All Comparisons'!$C$2:$C$561,$A21)+SUMIFS('Review Queue'!$AB$2:$AB$64,'Review Queue'!$C$2:$C$64,$A21)-SUMIFS('Review Queue'!$O$2:$O$64,'Review Queue'!$C$2:$C$64,$A21) -> 77 | G21: =SUMIFS('All Comparisons'!$P$2:$P$561,'All Comparisons'!$C$2:$C$561,$A21)+SUMIFS('Review Queue'!$AC$2:$AC$64,'Review Queue'!$C$2:$C$64,$A21)-SUMIFS('Review Queue'!$P$2:$P$64,'Review Queue'!$C$2:$C$64,$A21) -> 2 | H21: =SUMIFS('All Comparisons'!$Q$2:$Q$561,'All Comparisons'!$C$2:$C$561,$A21)+SUMIFS('Review Queue'!$AD$2:$AD$64,'Review Queue'!$C$2:$C$64,$A21)-SUMIFS('Review Queue'!$Q$2:$Q$64,'Review Queue'!$C$2:$C$64,$A21) -> 3 | I21: =IFERROR(F21/(F21+G21),0) -> 0.97468354 | J21: =IFERROR(F21/(F21+H21),0) -> 0.9625 | K21: =IFERROR(2*I21*J21/(I21+J21),0) -> 0.96855346 | L21: =COUNTIFS('Review Queue'!$C$2:$C$64,$A21,'Review Queue'!$Y$2:$Y$64,"<>Reviewed",'Review Queue'!$X$2:$X$64,"<>Yes") -> 5 | M21: =COUNTIFS('Review Queue'!$C$2:$C$64,$A21,'Review Queue'!$AA$2:$AA$64,"INCOMPLETE") -> 0
A22: KSA | B22: Ontvanger | C22: =COUNTIFS('All Comparisons'!$C$2:$C$561,$A22,'All Comparisons'!$D$2:$D$561,$B22)-COUNTIFS('Review Queue'!$C$2:$C$64,$A22,'Review Queue'!$D$2:$D$64,$B22,'Review Queue'!$X$2:$X$64,"Yes") -> 20 | D22: =SUMIFS('All Comparisons'!$R$2:$R$561,'All Comparisons'!$C$2:$C$561,$A22,'All Comparisons'!$D$2:$D$561,$B22)+SUMIFS('Review Queue'!$AE$2:$AE$64,'Review Queue'!$C$2:$C$64,$A22,'Review Queue'!$D$2:$D$64,$B22)-SUMIFS('Review Queue'!$R$2:$R$64,'Review Queue'!$C$2:$C$64,$A22,'Review Queue'!$D$2:$D$64,$B22) -> 17 | E22: =IFERROR(D22/C22,0) -> 0.85 | F22: =SUMIFS('All Comparisons'!$O$2:$O$561,'All Comparisons'!$C$2:$C$561,$A22,'All Comparisons'!$D$2:$D$561,$B22)+SUMIFS('Review Queue'!$AB$2:$AB$64,'Review Queue'!$C$2:$C$64,$A22,'Review Queue'!$D$2:$D$64,$B22)-SUMIFS('Review Queue'!$O$2:$O$64,'Review Queue'!$C$2:$C$64,$A22,'Review Queue'!$D$2:$D$64,$B22) -> 17 | G22: =SUMIFS('All Comparisons'!$P$2:$P$561,'All Comparisons'!$C$2:$C$561,$A22,'All Comparisons'!$D$2:$D$561,$B22)+SUMIFS('Review Queue'!$AC$2:$AC$64,'Review Queue'!$C$2:$C$64,$A22,'Review Queue'!$D$2:$D$64,$B22)-SUMIFS('Review Queue'!$P$2:$P$64,'Review Queue'!$C$2:$C$64,$A22,'Review Queue'!$D$2:$D$64,$B22) -> 3 | H22: =SUMIFS('All Comparisons'!$Q$2:$Q$561,'All Comparisons'!$C$2:$C$561,$A22,'All Comparisons'!$D$2:$D$561,$B22)+SUMIFS('Review Queue'!$AD$2:$AD$64,'Review Queue'!$C$2:$C$64,$A22,'Review Queue'!$D$2:$D$64,$B22)-SUMIFS('Review Queue'!$Q$2:$Q$64,'Review Queue'!$C$2:$C$64,$A22,'Review Queue'!$D$2:$D$64,$B22) -> 3 | I22: =IFERROR(F22/(F22+G22),0) -> 0.85 | J22: =IFERROR(F22/(F22+H22),0) -> 0.85 | K22: =IFERROR(2*I22*J22/(I22+J22),0) -> 0.85 | L22: =COUNTIFS('Review Queue'!$C$2:$C$64,$A22,'Review Queue'!$D$2:$D$64,$B22,'Review Queue'!$Y$2:$Y$64,"<>Reviewed",'Review Queue'!$X$2:$X$64,"<>Yes") -> 6 | M22: =COUNTIFS('Review Queue'!$C$2:$C$64,$A22,'Review Queue'!$D$2:$D$64,$B22,'Review Queue'!$AA$2:$AA$64,"INCOMPLETE") -> 0
A23: KSA | B23: Besluitvormend Orgaan | C23: =COUNTIFS('All Comparisons'!$C$2:$C$561,$A23,'All Comparisons'!$D$2:$D$561,$B23)-COUNTIFS('Review Queue'!$C$2:$C$64,$A23,'Review Queue'!$D$2:$D$64,$B23,'Review Queue'!$X$2:$X$64,"Yes") -> 20 | D23: =SUMIFS('All Comparisons'!$R$2:$R$561,'All Comparisons'!$C$2:$C$561,$A23,'All Comparisons'!$D$2:$D$561,$B23)+SUMIFS('Review Queue'!$AE$2:$AE$64,'Review Queue'!$C$2:$C$64,$A23,'Review Queue'!$D$2:$D$64,$B23)-SUMIFS('Review Queue'!$R$2:$R$64,'Review Queue'!$C$2:$C$64,$A23,'Review Queue'!$D$2:$D$64,$B23) -> 20 | E23: =IFERROR(D23/C23,0) -> 1 | F23: =SUMIFS('All Comparisons'!$O$2:$O$561,'All Comparisons'!$C$2:$C$561,$A23,'All Comparisons'!$D$2:$D$561,$B23)+SUMIFS('Review Queue'!$AB$2:$AB$64,'Review Queue'!$C$2:$C$64,$A23,'Review Queue'!$D$2:$D$64,$B23)-SUMIFS('Review Queue'!$O$2:$O$64,'Review Queue'!$C$2:$C$64,$A23,'Review Queue'!$D$2:$D$64,$B23) -> 20 | G23: =SUMIFS('All Comparisons'!$P$2:$P$561,'All Comparisons'!$C$2:$C$561,$A23,'All Comparisons'!$D$2:$D$561,$B23)+SUMIFS('Review Queue'!$AC$2:$AC$64,'Review Queue'!$C$2:$C$64,$A23,'Review Queue'!$D$2:$D$64,$B23)-SUMIFS('Review Queue'!$P$2:$P$64,'Review Queue'!$C$2:$C$64,$A23,'Review Queue'!$D$2:$D$64,$B23) -> 0 | H23: =SUMIFS('All Comparisons'!$Q$2:$Q$561,'All Comparisons'!$C$2:$C$561,$A23,'All Comparisons'!$D$2:$D$561,$B23)+SUMIFS('Review Queue'!$AD$2:$AD$64,'Review Queue'!$C$2:$C$64,$A23,'Review Queue'!$D$2:$D$64,$B23)-SUMIFS('Review Queue'!$Q$2:$Q$64,'Review Queue'!$C$2:$C$64,$A23,'Review Queue'!$D$2:$D$64,$B23) -> 0 | I23: =IFERROR(F23/(F23+G23),0) -> 1 | J23: =IFERROR(F23/(F23+H23),0) -> 1 | K23: =IFERROR(2*I23*J23/(I23+J23),0) -> 1 | L23: =COUNTIFS('Review Queue'!$C$2:$C$64,$A23,'Review Queue'!$D$2:$D$64,$B23,'Review Queue'!$Y$2:$Y$64,"<>Reviewed",'Review Queue'!$X$2:$X$64,"<>Yes") -> 1 | M23: =COUNTIFS('Review Queue'!$C$2:$C$64,$A23,'Review Queue'!$D$2:$D$64,$B23,'Review Queue'!$AA$2:$AA$64,"INCOMPLETE") -> 0
A24: KSA | B24: Rechtshandeling | C24: =COUNTIFS('All Comparisons'!$C$2:$C$561,$A24,'All Comparisons'!$D$2:$D$561,$B24)-COUNTIFS('Review Queue'!$C$2:$C$64,$A24,'Review Queue'!$D$2:$D$64,$B24,'Review Queue'!$X$2:$X$64,"Yes") -> 20 | D24: =SUMIFS('All Comparisons'!$R$2:$R$561,'All Comparisons'!$C$2:$C$561,$A24,'All Comparisons'!$D$2:$D$561,$B24)+SUMIFS('Review Queue'!$AE$2:$AE$64,'Review Queue'!$C$2:$C$64,$A24,'Review Queue'!$D$2:$D$64,$B24)-SUMIFS('Review Queue'!$R$2:$R$64,'Review Queue'!$C$2:$C$64,$A24,'Review Queue'!$D$2:$D$64,$B24) -> 20 | E24: =IFERROR(D24/C24,0) -> 1 | F24: =SUMIFS('All Comparisons'!$O$2:$O$561,'All Comparisons'!$C$2:$C$561,$A24,'All Comparisons'!$D$2:$D$561,$B24)+SUMIFS('Review Queue'!$AB$2:$AB$64,'Review Queue'!$C$2:$C$64,$A24,'Review Queue'!$D$2:$D$64,$B24)-SUMIFS('Review Queue'!$O$2:$O$64,'Review Queue'!$C$2:$C$64,$A24,'Review Queue'!$D$2:$D$64,$B24) -> 20 | G24: =SUMIFS('All Comparisons'!$P$2:$P$561,'All Comparisons'!$C$2:$C$561,$A24,'All Comparisons'!$D$2:$D$561,$B24)+SUMIFS('Review Queue'!$AC$2:$AC$64,'Review Queue'!$C$2:$C$64,$A24,'Review Queue'!$D$2:$D$64,$B24)-SUMIFS('Review Queue'!$P$2:$P$64,'Review Queue'!$C$2:$C$64,$A24,'Review Queue'!$D$2:$D$64,$B24) -> 0 | H24: =SUMIFS('All Comparisons'!$Q$2:$Q$561,'All Comparisons'!$C$2:$C$561,$A24,'All Comparisons'!$D$2:$D$561,$B24)+SUMIFS('Review Queue'!$AD$2:$AD$64,'Review Queue'!$C$2:$C$64,$A24,'Review Queue'!$D$2:$D$64,$B24)-SUMIFS('Review Queue'!$Q$2:$Q$64,'Review Queue'!$C$2:$C$64,$A24,'Review Queue'!$D$2:$D$64,$B24) -> 0 | I24: =IFERROR(F24/(F24+G24),0) -> 1 | J24: =IFERROR(F24/(F24+H24),0) -> 1 | K24: =IFERROR(2*I24*J24/(I24+J24),0) -> 1 | L24: =COUNTIFS('Review Queue'!$C$2:$C$64,$A24,'Review Queue'!$D$2:$D$64,$B24,'Review Queue'!$Y$2:$Y$64,"<>Reviewed",'Review Queue'!$X$2:$X$64,"<>Yes") -> 0 | M24: =COUNTIFS('Review Queue'!$C$2:$C$64,$A24,'Review Queue'!$D$2:$D$64,$B24,'Review Queue'!$AA$2:$AA$64,"INCOMPLETE") -> 0
A25: KSA | B25: Rechtsobject | C25: =COUNTIFS('All Comparisons'!$C$2:$C$561,$A25,'All Comparisons'!$D$2:$D$561,$B25)-COUNTIFS('Review Queue'!$C$2:$C$64,$A25,'Review Queue'!$D$2:$D$64,$B25,'Review Queue'!$X$2:$X$64,"Yes") -> 20 | D25: =SUMIFS('All Comparisons'!$R$2:$R$561,'All Comparisons'!$C$2:$C$561,$A25,'All Comparisons'!$D$2:$D$561,$B25)+SUMIFS('Review Queue'!$AE$2:$AE$64,'Review Queue'!$C$2:$C$64,$A25,'Review Queue'!$D$2:$D$64,$B25)-SUMIFS('Review Queue'!$R$2:$R$64,'Review Queue'!$C$2:$C$64,$A25,'Review Queue'!$D$2:$D$64,$B25) -> 20 | E25: =IFERROR(D25/C25,0) -> 1 | F25: =SUMIFS('All Comparisons'!$O$2:$O$561,'All Comparisons'!$C$2:$C$561,$A25,'All Comparisons'!$D$2:$D$561,$B25)+SUMIFS('Review Queue'!$AB$2:$AB$64,'Review Queue'!$C$2:$C$64,$A25,'Review Queue'!$D$2:$D$64,$B25)-SUMIFS('Review Queue'!$O$2:$O$64,'Review Queue'!$C$2:$C$64,$A25,'Review Queue'!$D$2:$D$64,$B25) -> 20 | G25: =SUMIFS('All Comparisons'!$P$2:$P$561,'All Comparisons'!$C$2:$C$561,$A25,'All Comparisons'!$D$2:$D$561,$B25)+SUMIFS('Review Queue'!$AC$2:$AC$64,'Review Queue'!$C$2:$C$64,$A25,'Review Queue'!$D$2:$D$64,$B25)-SUMIFS('Review Queue'!$P$2:$P$64,'Review Queue'!$C$2:$C$64,$A25,'Review Queue'!$D$2:$D$64,$B25) -> 0 | H25: =SUMIFS('All Comparisons'!$Q$2:$Q$561,'All Comparisons'!$C$2:$C$561,$A25,'All Comparisons'!$D$2:$D$561,$B25)+SUMIFS('Review Queue'!$AD$2:$AD$64,'Review Queue'!$C$2:$C$64,$A25,'Review Queue'!$D$2:$D$64,$B25)-SUMIFS('Review Queue'!$Q$2:$Q$64,'Review Queue'!$C$2:$C$64,$A25,'Review Queue'!$D$2:$D$64,$B25) -> 0 | I25: =IFERROR(F25/(F25+G25),0) -> 1 | J25: =IFERROR(F25/(F25+H25),0) -> 1 | K25: =IFERROR(2*I25*J25/(I25+J25),0) -> 1 | L25: =COUNTIFS('Review Queue'!$C$2:$C$64,$A25,'Review Queue'!$D$2:$D$64,$B25,'Review Queue'!$Y$2:$Y$64,"<>Reviewed",'Review Queue'!$X$2:$X$64,"<>Yes") -> 1 | M25: =COUNTIFS('Review Queue'!$C$2:$C$64,$A25,'Review Queue'!$D$2:$D$64,$B25,'Review Queue'!$AA$2:$AA$64,"INCOMPLETE") -> 0
A26: KSA | B26: Overall | C26: =COUNTIFS('All Comparisons'!$C$2:$C$561,$A26)-COUNTIFS('Review Queue'!$C$2:$C$64,$A26,'Review Queue'!$X$2:$X$64,"Yes") -> 80 | D26: =SUMIFS('All Comparisons'!$R$2:$R$561,'All Comparisons'!$C$2:$C$561,$A26)+SUMIFS('Review Queue'!$AE$2:$AE$64,'Review Queue'!$C$2:$C$64,$A26)-SUMIFS('Review Queue'!$R$2:$R$64,'Review Queue'!$C$2:$C$64,$A26) -> 77 | E26: =IFERROR(D26/C26,0) -> 0.9625 | F26: =SUMIFS('All Comparisons'!$O$2:$O$561,'All Comparisons'!$C$2:$C$561,$A26)+SUMIFS('Review Queue'!$AB$2:$AB$64,'Review Queue'!$C$2:$C$64,$A26)-SUMIFS('Review Queue'!$O$2:$O$64,'Review Queue'!$C$2:$C$64,$A26) -> 77 | G26: =SUMIFS('All Comparisons'!$P$2:$P$561,'All Comparisons'!$C$2:$C$561,$A26)+SUMIFS('Review Queue'!$AC$2:$AC$64,'Review Queue'!$C$2:$C$64,$A26)-SUMIFS('Review Queue'!$P$2:$P$64,'Review Queue'!$C$2:$C$64,$A26) -> 3 | H26: =SUMIFS('All Comparisons'!$Q$2:$Q$561,'All Comparisons'!$C$2:$C$561,$A26)+SUMIFS('Review Queue'!$AD$2:$AD$64,'Review Queue'!$C$2:$C$64,$A26)-SUMIFS('Review Queue'!$Q$2:$Q$64,'Review Queue'!$C$2:$C$64,$A26) -> 3 | I26: =IFERROR(F26/(F26+G26),0) -> 0.9625 | J26: =IFERROR(F26/(F26+H26),0) -> 0.9625 | K26: =IFERROR(2*I26*J26/(I26+J26),0) -> 0.9625 | L26: =COUNTIFS('Review Queue'!$C$2:$C$64,$A26,'Review Queue'!$Y$2:$Y$64,"<>Reviewed",'Review Queue'!$X$2:$X$64,"<>Yes") -> 8 | M26: =COUNTIFS('Review Queue'!$C$2:$C$64,$A26,'Review Queue'!$AA$2:$AA$64,"INCOMPLETE") -> 0
A27: ROT | B27: Ontvanger | C27: =COUNTIFS('All Comparisons'!$C$2:$C$561,$A27,'All Comparisons'!$D$2:$D$561,$B27)-COUNTIFS('Review Queue'!$C$2:$C$64,$A27,'Review Queue'!$D$2:$D$64,$B27,'Review Queue'!$X$2:$X$64,"Yes") -> 20 | D27: =SUMIFS('All Comparisons'!$R$2:$R$561,'All Comparisons'!$C$2:$C$561,$A27,'All Comparisons'!$D$2:$D$561,$B27)+SUMIFS('Review Queue'!$AE$2:$AE$64,'Review Queue'!$C$2:$C$64,$A27,'Review Queue'!$D$2:$D$64,$B27)-SUMIFS('Review Queue'!$R$2:$R$64,'Review Queue'!$C$2:$C$64,$A27,'Review Queue'!$D$2:$D$64,$B27) -> 6 | E27: =IFERROR(D27/C27,0) -> 0.3 | F27: =SUMIFS('All Comparisons'!$O$2:$O$561,'All Comparisons'!$C$2:$C$561,$A27,'All Comparisons'!$D$2:$D$561,$B27)+SUMIFS('Review Queue'!$AB$2:$AB$64,'Review Queue'!$C$2:$C$64,$A27,'Review Queue'!$D$2:$D$64,$B27)-SUMIFS('Review Queue'!$O$2:$O$64,'Review Queue'!$C$2:$C$64,$A27,'Review Queue'!$D$2:$D$64,$B27) -> 0 | G27: =SUMIFS('All Comparisons'!$P$2:$P$561,'All Comparisons'!$C$2:$C$561,$A27,'All Comparisons'!$D$2:$D$561,$B27)+SUMIFS('Review Queue'!$AC$2:$AC$64,'Review Queue'!$C$2:$C$64,$A27,'Review Queue'!$D$2:$D$64,$B27)-SUMIFS('Review Queue'!$P$2:$P$64,'Review Queue'!$C$2:$C$64,$A27,'Review Queue'!$D$2:$D$64,$B27) -> 0 | H27: =SUMIFS('All Comparisons'!$Q$2:$Q$561,'All Comparisons'!$C$2:$C$561,$A27,'All Comparisons'!$D$2:$D$561,$B27)+SUMIFS('Review Queue'!$AD$2:$AD$64,'Review Queue'!$C$2:$C$64,$A27,'Review Queue'!$D$2:$D$64,$B27)-SUMIFS('Review Queue'!$Q$2:$Q$64,'Review Queue'!$C$2:$C$64,$A27,'Review Queue'!$D$2:$D$64,$B27) -> 14 | I27: =IFERROR(F27/(F27+G27),0) -> 0 | J27: =IFERROR(F27/(F27+H27),0) -> 0 | K27: =IFERROR(2*I27*J27/(I27+J27),0) -> 0 | L27: =COUNTIFS('Review Queue'!$C$2:$C$64,$A27,'Review Queue'!$D$2:$D$64,$B27,'Review Queue'!$Y$2:$Y$64,"<>Reviewed",'Review Queue'!$X$2:$X$64,"<>Yes") -> 14 | M27: =COUNTIFS('Review Queue'!$C$2:$C$64,$A27,'Review Queue'!$D$2:$D$64,$B27,'Review Queue'!$AA$2:$AA$64,"INCOMPLETE") -> 0
A28: ROT | B28: Besluitvormend Orgaan | C28: =COUNTIFS('All Comparisons'!$C$2:$C$561,$A28,'All Comparisons'!$D$2:$D$561,$B28)-COUNTIFS('Review Queue'!$C$2:$C$64,$A28,'Review Queue'!$D$2:$D$64,$B28,'Review Queue'!$X$2:$X$64,"Yes") -> 20 | D28: =SUMIFS('All Comparisons'!$R$2:$R$561,'All Comparisons'!$C$2:$C$561,$A28,'All Comparisons'!$D$2:$D$561,$B28)+SUMIFS('Review Queue'!$AE$2:$AE$64,'Review Queue'!$C$2:$C$64,$A28,'Review Queue'!$D$2:$D$64,$B28)-SUMIFS('Review Queue'!$R$2:$R$64,'Review Queue'!$C$2:$C$64,$A28,'Review Queue'!$D$2:$D$64,$B28) -> 20 | E28: =IFERROR(D28/C28,0) -> 1 | F28: =SUMIFS('All Comparisons'!$O$2:$O$561,'All Comparisons'!$C$2:$C$561,$A28,'All Comparisons'!$D$2:$D$561,$B28)+SUMIFS('Review Queue'!$AB$2:$AB$64,'Review Queue'!$C$2:$C$64,$A28,'Review Queue'!$D$2:$D$64,$B28)-SUMIFS('Review Queue'!$O$2:$O$64,'Review Queue'!$C$2:$C$64,$A28,'Review Queue'!$D$2:$D$64,$B28) -> 20 | G28: =SUMIFS('All Comparisons'!$P$2:$P$561,'All Comparisons'!$C$2:$C$561,$A28,'All Comparisons'!$D$2:$D$561,$B28)+SUMIFS('Review Queue'!$AC$2:$AC$64,'Review Queue'!$C$2:$C$64,$A28,'Review Queue'!$D$2:$D$64,$B28)-SUMIFS('Review Queue'!$P$2:$P$64,'Review Queue'!$C$2:$C$64,$A28,'Review Queue'!$D$2:$D$64,$B28) -> 0 | H28: =SUMIFS('All Comparisons'!$Q$2:$Q$561,'All Comparisons'!$C$2:$C$561,$A28,'All Comparisons'!$D$2:$D$561,$B28)+SUMIFS('Review Queue'!$AD$2:$AD$64,'Review Queue'!$C$2:$C$64,$A28,'Review Queue'!$D$2:$D$64,$B28)-SUMIFS('Review Queue'!$Q$2:$Q$64,'Review Queue'!$C$2:$C$64,$A28,'Review Queue'!$D$2:$D$64,$B28) -> 0 | I28: =IFERROR(F28/(F28+G28),0) -> 1 | J28: =IFERROR(F28/(F28+H28),0) -> 1 | K28: =IFERROR(2*I28*J28/(I28+J28),0) -> 1 | L28: =COUNTIFS('Review Queue'!$C$2:$C$64,$A28,'Review Queue'!$D$2:$D$64,$B28,'Review Queue'!$Y$2:$Y$64,"<>Reviewed",'Review Queue'!$X$2:$X$64,"<>Yes") -> 0 | M28: =COUNTIFS('Review Queue'!$C$2:$C$64,$A28,'Review Queue'!$D$2:$D$64,$B28,'Review Queue'!$AA$2:$AA$64,"INCOMPLETE") -> 0
A29: ROT | B29: Rechtshandeling | C29: =COUNTIFS('All Comparisons'!$C$2:$C$561,$A29,'All Comparisons'!$D$2:$D$561,$B29)-COUNTIFS('Review Queue'!$C$2:$C$64,$A29,'Review Queue'!$D$2:$D$64,$B29,'Review Queue'!$X$2:$X$64,"Yes") -> 20 | D29: =SUMIFS('All Comparisons'!$R$2:$R$561,'All Comparisons'!$C$2:$C$561,$A29,'All Comparisons'!$D$2:$D$561,$B29)+SUMIFS('Review Queue'!$AE$2:$AE$64,'Review Queue'!$C$2:$C$64,$A29,'Review Queue'!$D$2:$D$64,$B29)-SUMIFS('Review Queue'!$R$2:$R$64,'Review Queue'!$C$2:$C$64,$A29,'Review Queue'!$D$2:$D$64,$B29) -> 20 | E29: =IFERROR(D29/C29,0) -> 1 | F29: =SUMIFS('All Comparisons'!$O$2:$O$561,'All Comparisons'!$C$2:$C$561,$A29,'All Comparisons'!$D$2:$D$561,$B29)+SUMIFS('Review Queue'!$AB$2:$AB$64,'Review Queue'!$C$2:$C$64,$A29,'Review Queue'!$D$2:$D$64,$B29)-SUMIFS('Review Queue'!$O$2:$O$64,'Review Queue'!$C$2:$C$64,$A29,'Review Queue'!$D$2:$D$64,$B29) -> 20 | G29: =SUMIFS('All Comparisons'!$P$2:$P$561,'All Comparisons'!$C$2:$C$561,$A29,'All Comparisons'!$D$2:$D$561,$B29)+SUMIFS('Review Queue'!$AC$2:$AC$64,'Review Queue'!$C$2:$C$64,$A29,'Review Queue'!$D$2:$D$64,$B29)-SUMIFS('Review Queue'!$P$2:$P$64,'Review Queue'!$C$2:$C$64,$A29,'Review Queue'!$D$2:$D$64,$B29) -> 0 | H29: =SUMIFS('All Comparisons'!$Q$2:$Q$561,'All Comparisons'!$C$2:$C$561,$A29,'All Comparisons'!$D$2:$D$561,$B29)+SUMIFS('Review Queue'!$AD$2:$AD$64,'Review Queue'!$C$2:$C$64,$A29,'Review Queue'!$D$2:$D$64,$B29)-SUMIFS('Review Queue'!$Q$2:$Q$64,'Review Queue'!$C$2:$C$64,$A29,'Review Queue'!$D$2:$D$64,$B29) -> 0 | I29: =IFERROR(F29/(F29+G29),0) -> 1 | J29: =IFERROR(F29/(F29+H29),0) -> 1 | K29: =IFERROR(2*I29*J29/(I29+J29),0) -> 1 | L29: =COUNTIFS('Review Queue'!$C$2:$C$64,$A29,'Review Queue'!$D$2:$D$64,$B29,'Review Queue'!$Y$2:$Y$64,"<>Reviewed",'Review Queue'!$X$2:$X$64,"<>Yes") -> 1 | M29: =COUNTIFS('Review Queue'!$C$2:$C$64,$A29,'Review Queue'!$D$2:$D$64,$B29,'Review Queue'!$AA$2:$AA$64,"INCOMPLETE") -> 0
